Workbook

Sheet Overview
A1: This spreadsheet was designed for entering and converting the survey data from Willie Stanton's survey notebooks into digital data which could be processed by Survex and Therion cave survey programs. The philosopy for the data entry is to retain as close to the original format of all data as possible at the data entry stage. This enables the data in the spreadsheet to be easily identified with the corresponding data in the original survey notebooks, for cross checking. The spreadsheet is organised into a number of worksheets as described below.
A3: Raw Data
A4: This sheet is where the raw data entry is being made. The data is entered in columns in as close as possible to the format written in the original notebooks. Page numbers for the original notebooks are specified in addition to the actual page number from the source PDF documents to help indicate the source pages of the data.
A6: Interpreted Data
A7: This sheet is where the data interpretation is done, converting different formatting of numbers into numeric data which the spreadsheet can do operations on. E.g. Angles given in degrees-seconds are converted into decimal degrees. Clino readings for legs where a vertical drop was quoted rather than a clino angle have the clino angle calculated from the other data for the leg. Cells with calculated values using different formulae are coloured differently to help see where data is being derived from (e.g. calculated clino reading as green instead of blue for interpreted clino reading determined from degrees and minutes). This sheet also contains check-sum calculations ('calc' columns) to help look for data errors. Vertical and horizontal distances are calculated and compared to the values entered in the Raw Data sheet from the notebooks, and if these differ significantly then the calculated values are coloured red to highlight possible errors in data entry (or in the original source data). Some length values in the original notes appear to be horizontal distance (where a vertical drop is noted instead of a clino reading), but some are the true distance between stations. When the error check-sum detects these, the interpreted length of the leg is calculated from the horiztonal and vertical distances given (and the cell is coloured green to indicate this alternative formula has been used).
A9: Survex Formatted
A10: This sheet contains data in normal survex format for cutting and pasting into Survex text files for processing. All data is converted into metric decimal units on this worksheet.
A12: Therion Formatted
A13: This sheet contains the data reformatted for Therion survey data files. As much of the original formatting as possible is retained here so that the data in the Therion data files is easier to match to the original survey notebooks as possible.
A15: The original survey notebooks were obtained as scanned documents in PDF format from the MCRA website:
A16: http://www.mcra.org.uk/logbooks/?dir=Willie%20Stanton%2FSurvey%20Notes
A18: This spreadsheet is stored in the BCA Cave Registry Data Archive:
A19: http://cave-registry.org.uk/

Sheet Raw Data
A1: p. 45-46 | B1: (=PDF p.49-50)
A2: 21st July 1951 | B2: W.I.Stanton | C2: SWILDONS HOLE | M2: Compass bearings magnetic 11(deg)30' W
E3: Looking Forward
A4: Sta. | B4: Sta. | C4: Ht Rf | D4: Dp Fl | E4: Width L | F4: Width R | G4: FS | H4: BS | I4: Bearing | J4: Distance | K4: Fore Clino | M4: Hor Dist. | N4: Vert Dist. | O4: Dp. Below sump I | P4: Notes
A5: A | B5: B | C5: 20 | D5: - | E5: 4 | F5: 4(19' in aven) | G5: - | H5: 103 | I5: 283 | J5: 21 | K5: 8 30 | M5: 20.8 | N5: 3.1 | P5: A is at the base of the cable spike on the downstream side of Sump I
A6: B | B6: C | C6: 6 | D6: 3.5 | E6: 3 | F6: 6 | G6: 322 30 | H6: - | I6: 322 30 | J6: 27 | K6: ="-9 30" -> -9 30 | M6: 26.7 | N6: -4.5 | O6: 3.1 | P6: B is on a rock at upstream end of pool
A7: C | B7: D | C7: 7 | D7: - | E7: 4 | F7: 2 | G7: - | H7: 83 | I7: 263 | J7: 37 | K7: rise of 1.5 feet | M7: 37 | N7: 1.5 | O7: -1.4 | P7: C is on edge of pool 10' before Duck I
A8: D | B8: E | C8: 25 | D8: 2 | E8: - | F8: 10 | G8: 192 30 | H8: - | I8: 192 30 | J8: 16.2 | K8: 4 30 | M8: 16.1 | N8: 1.3 | O8: 0.1 | P8: D is in stream. Big rock (start of New Series survey) 10' away at 350 (deg). Big passage starts as continuation of Howards Dig.
A9: E | B9: F | C9: 25 | D9: 4.5 | E9: 6 | F9: - | G9: - | H9: 78 | I9: 258 | J9: 47 | K9: ="-5 30" -> -5 30 | M9: 46.8 | N9: -4.5 | O9: 1.4
A10: F | B10: G | C10: 4 | D10: 2 | E10: 0.5 | F10: 3 (30 in B.Place(?)) | G10: 292 | H10: - | I10: 292 | J10: 48 | K10: fall of 2.5 feet | M10: 48 | N10: -2.5 | O10: -3.1 | P10: At 40' the roof lowers suddenly to Creep I. The big Bedding Plane passage comes in on the right, from -5' to 40'
A11: G | B11: H | C11: 2.5 | D11: 0.5 | E11: 3.5 | F11: 7 | G11: - | H11: 159 | I11: 339 | J11: 36 | K11: level | M11: 36 | N11: 0 | O11: -5.6
A12: H | B12: I | C12: 15 | D12: 1 | E12: 10 | F12: 3 | G12: 247 | H12: - | I12: 247 | J12: 31 | K12: ="-2 30" -> -2 30 | M12: 31 | N12: -1.3 | O12: -5.6
A13: I | B13: J | C13: 15 | D13: 1 | E13: 8 | F13: 2 | G13: - | H13: 95 | I13: 275 | J13: 26 | K13: 2 | M13: 26 | N13: 0.9 | O13: -6.9
A14: J | B14: K | C14: 8 | D14: 3 | E14: 1 | F14: 2 | G14: 320 | H14: - | I14: 320 | J14: 26.5 | K14: 1 | M14: 26.5 | N14: 0.5 | O14: -6 | P14: Pots
A15: K | B15: L | C15: 25 | D15: 4.5 | E15: - | F15: 4 | G15: - | H15: 193 | I15: 13 | J15: 17.5 | K15: -9 | M15: 17.3 | N15: -2.7 | O15: -5.5 | P15: Pots
A16: L | B16: M | C16: 20 | D16: 3 | E16: 2 | F16: 2 | G16: 299 | H16: - | I16: 299 | J16: 33 | K16: -3 | M16: 33 | N16: -1.7 | O16: -8.2 | P16: L is at foot of climb to Approach passage. Clay fill remains 6' up on left wall.
A17: M | B17: N | C17: 15 | D17: 7 | E17: 4 | F17: - | G17: - | H17: 142 | I17: 322 | J17: 43 | K17: -7.3 | M17: 42.7 | N17: -5.6 | O17: -9.9 | P17: Pots
A18: N | B18: O | C18: 25 | D18: 3 | E18: 2 | F18: 1 | G18: 281 | H18: - | I18: 281 | J18: 15.5 | K18: -2 | M18: 15.5 | N18: -0.5 | O18: -15.5 | P18: Pots
A19: O | B19: P | C19: 40 | D19: 4.5 | E19: 2 | F19: 2 | G19: - | H19: 127 | I19: 307 | J19: 56 | K19: -5 | M19: 55.8 | N19: -4.9 | O19: -16 | P19: Pots. Very pretty coral on left wall
A20: P | B20: Q | C20: 40 | D20: 3 | E20: 2 | F20: 3 | G20: 283 | H20: - | I20: 283 | J20: 15.8 | K20: ="-0 15" -> -0 15 | M20: 15.8 | N20: -0.1 | O20: -20.9
A21: Q | B21: R | C21: 40 | D21: 4 | E21: 4 | F21: - | G21: - | H21: 37 | I21: 217 | J21: 15.3 | K21: fall of 4 feet | M21: 15.3 | N21: -4 | O21: -21 | P21: 1.5 foot deep pool starts at P.
A22: R | B22: S | C22: 40 | D22: - | E22: - | F22: 4 | G22: 310 | H22: - | I22: 310 | J22: 39.5 | K22: rise of 4 feet | M22: 39.5 | N22: 4 | O22: -25 | P22: Pool 2.5' deep at R, ends 15' on. Scalloping as in Goughs 1st Sandy Chamber.
A23: S | B23: T | C23: 12 | D23: 4.5 | E23: 8 | F23: - | G23: - | H23: 58 | I23: 238 | J23: 39.6 | K23: ="-2 30" -> -2 30 | M23: 39.6 | N23: -1.9 | O23: -21 | P23: S is marked on wall. At 20' there is a muddy chamber overhead.
A24: T | B24: U | C24: 2 | D24: 2.5 | E24: 15 | F24: 6 | G24: 148 | H24: - | I24: 148 | J24: 49 | K24: fall of 1.7 feet | M24: 49 | N24: -1.7 | O24: -22.9
A25: U | C25: 1.5 | D25: 1.5 | O25: -24.6 | P25: Beasts (or Pearls? Not clear in scan) seen here. Total = 650'
A26: A1 | B26: B1 | C26: - | D26: 1 | E26: 1 | F26: 0.5 | G26: - | H26: 326 | I26: 146 | J26: 30.4 | K26: level | M26: 30.4 | N26: - | P26: A1 is far end of "Priddy Green" passage. At choke
A27: B1 | B27: C1 | C27: 4 | D27: 1 | E27: 10 | F27: 2 | G27: 248 | H27: - | I27: 248 | J27: 37.5 | K27: ="-6 00" -> -6 00 | M27: 37.3 | N27: -3.9 | O27: 11 | P27: B1 is ent to P.G. pass, above stalagmite keloid (sp.?)
A28: p. 47-50 | B28: (=PDF p.51-54)
A29: 5th August 1951 | B29: SWILDONS HOLE SURVEY | M29: CONTINUED | O29: Compass bearings magnetic 11(deg)30' W
A30: C1 | B30: D1 | C30: 5 | D30: 6 | E30: 15 | F30: 4 | G30: - | H30: 85 | I30: 265 | J30: 11.8 | K30: -24 | M30: 10.8 | N30: -4.8 | O30: 7.1 | P30: On rocky bank.
A31: D1 | B31: A | C31: 2 | D31: 2.3 | E31: 10 | F31: 4 | G31: 251 | H31: - | I31: 251 | J31: 36.8 | K31: water level | M31: 36.6 | N31: -2.3 | O31: 2.3 | P31: D1 to near side of Sump I 11.8'. D1 to far side of Sump I 18'. D1 is in pool at stake for cable.
A32: U | B32: V | C32: 1.5 | D32: 1.5 | E32: 2.5 | F32: 15 | G32: - | H32: 6 30 | I32: 186 30 | J32: 29 | K32: water level | M32: 29 | N32: - | O32: -24.6 | P32: Lake begins as 10'. (Little sketch)
A33: V | B33: W | C33: 15 | D33: - | E33: 2 | F33: 4 | G33: 141 30 | H33: - | I33: 141 30 | J33: 33.8 | K33: water level | M33: 33.8 | N33: - | O33: -26.1 | P33: Lake
A34: W | B34: X | C34: 4 | D34: - | E34: 0.5 | F34: 8 | G34: 132 10 | H34: - | I34: 132 10 | J34: 47 | K34: water level | M34: 47 | N34: - | O34: -26.1 | P34: Bearing from 2' to right. W to near side Duck II = 3.5. W to far side Duck II = 20.4
A35: X | B35: Y | C35: 12 | D35: - | E35: 2 | F35: 10 | G35: - | H35: 354 | I35: 174 | J35: 83.5 | K35: fall 0.7' | M35: 83.5 | N35: -0.7 | O35: -26.1 | P35: Y at lip of Sump II, 3" air space goes on 10 more
A36: Y | C36: 0.4 (12) | D36: - | E36: 4 | F36: 2 | O36: -26.8 | P36: (Little sketch). Total 1010'
A37: T | B37: Ri | C37: ="/" -> / | D37: ="/" -> / | E37: ="/" -> / | F37: ="/" -> / | G37: 19 | H37: - | I37: 19 | J37: 22.1 | K37: 20 | M37: 20.8 | N37: 7.6 | O37: -22.9
A38: Ri | B38: Rii | C38: 1 | D38: 0.5 | E38: 8 | F38: 8 | G38: 315 | H38: - | I38: 315 | J38: 46 | K38: -3 | M38: 45.9 | N38: -2.4 | O38: -15.3 | P38: Sump on left at 41' feet
A39: Rii | B39: Riii | C39: 1 | D39: 2 | E39: 4 | F39: 4 | G39: 348 | H39: - | I39: 348 | J39: 32 | K39: 2 | M39: 32 | N39: 1.1 | O39: -17.7 | P39: Bearing from 3 feet to left
A40: Riii | B40: Riv | C40: 2 | D40: 1.5 | E40: 5 | F40: 2 | G40: 284 | H40: - | I40: 284 | J40: 27.3 | K40: fall 4 feet | M40: 27.3 | N40: -4 | O40: -16.6 | P40: Bearing from 2' to left. Iv is Muddy Sump. Dp below Sump I is 20.6 feet. Total 1127'
...

Sheet Interpreted Data
A1: =IF('Raw Data'!A1="","",'Raw Data'!A1) -> p. 45-46 | B1: =IF('Raw Data'!B1="","",'Raw Data'!B1) -> (=PDF p.49-50) | C1: =IF('Raw Data'!C1="","",'Raw Data'!C1) | D1: =IF('Raw Data'!D1="","",'Raw Data'!D1) | E1: =IF('Raw Data'!E1="","",'Raw Data'!E1) | F1: =IF('Raw Data'!F1="","",'Raw Data'!F1) | G1: =IF('Raw Data'!G1="","",'Raw Data'!G1) | H1: =IF('Raw Data'!H1="","",'Raw Data'!H1) | ... O1: =IF('Raw Data'!O1="","",'Raw Data'!O1) | Q1: =" " | R1: Reformatted Angles | W1: Calc.
A2: =IF('Raw Data'!A2="","",'Raw Data'!A2) -> 21st July 1951 | B2: =IF('Raw Data'!B2="","",'Raw Data'!B2) -> W.I.Stanton | C2: =IF('Raw Data'!C2="","",'Raw Data'!C2) -> SWILDONS HOLE | D2: =IF('Raw Data'!D2="","",'Raw Data'!D2) | E2: =IF('Raw Data'!E2="","",'Raw Data'!E2) | F2: =IF('Raw Data'!F2="","",'Raw Data'!F2) | G2: =IF('Raw Data'!G2="","",'Raw Data'!G2) | H2: =IF('Raw Data'!H2="","",'Raw Data'!H2) | ... O2: =IF('Raw Data'!O2="","",'Raw Data'!O2) | Q2: =" "
A3: =IF('Raw Data'!A3="","",'Raw Data'!A3) | B3: =IF('Raw Data'!B3="","",'Raw Data'!B3) | C3: =IF('Raw Data'!C3="","",'Raw Data'!C3) | D3: =IF('Raw Data'!D3="","",'Raw Data'!D3) | E3: =IF('Raw Data'!E3="","",'Raw Data'!E3) -> Looking Forward | G3: =IF('Raw Data'!G3="","",'Raw Data'!G3) | H3: =IF('Raw Data'!H3="","",'Raw Data'!H3) | I3: =IF('Raw Data'!I3="","",'Raw Data'!I3) | J3: =IF('Raw Data'!J3="","",'Raw Data'!J3) | K3: =IF('Raw Data'!K3="","",'Raw Data'!K3) | Q3: =" "
A4: =IF('Raw Data'!A4="","",'Raw Data'!A4) -> Sta. | B4: =IF('Raw Data'!B4="","",'Raw Data'!B4) -> Sta. | C4: =IF('Raw Data'!C4="","",'Raw Data'!C4) -> Ht Rf | D4: =IF('Raw Data'!D4="","",'Raw Data'!D4) -> Dp Fl | E4: =IF('Raw Data'!E4="","",'Raw Data'!E4) -> Width L | F4: =IF('Raw Data'!F4="","",'Raw Data'!F4) -> Width R | G4: =IF('Raw Data'!G4="","",'Raw Data'!G4) -> FS | H4: =IF('Raw Data'!H4="","",'Raw Data'!H4) -> BS | ... O4: =IF('Raw Data'!O4="","",'Raw Data'!O4) -> Dp. Below sump I | Q4: =" " | R4: =G4 -> FS | S4: =H4 -> BS | T4: =I4 -> Bearing | U4: =K4 -> Fore Clino | W4: Horz. Dist. | X4: Vert. Dist. | Y4: Bearing from FS/BS | Z4: Depth below sump 1
A5: =IF('Raw Data'!A5="","",'Raw Data'!A5) -> A | B5: =IF('Raw Data'!B5="","",'Raw Data'!B5) -> B | C5: =IF('Raw Data'!C5="","",'Raw Data'!C5) -> 20 | D5: =IF('Raw Data'!D5="","",'Raw Data'!D5) -> - | E5: =IF('Raw Data'!E5="","",'Raw Data'!E5) -> 4 | F5: =IF('Raw Data'!F5="","",'Raw Data'!F5) -> 4(19' in aven) | G5: =IF('Raw Data'!G5="/","-",IF('Raw Data'!G5="","-",SUBSTITUTE('Raw Data'!G5," ",":",1))) -> - | H5: =IF('Raw Data'!H5="/","-",IF('Raw Data'!H5="","-",SUBSTITUTE('Raw Data'!H5," ",":",1))) -> 103 | I5: =IF('Raw Data'!I5="/","-",IF('Raw Data'!I5="","-",SUBSTITUTE('Raw Data'!I5," ",":",1))) -> 283 | J5: =IF('Raw Data'!J5="",IF(LEN(K5)>6,SQRT('Raw Data'!M5^2+N5^2),""),'Raw Data'!J5) -> 21 | K5: =IF('Raw Data'!K5="","",IF(LEN('Raw Data'!K5)<7,SUBSTITUTE('Raw Data'!K5," ",":",1),'Raw Data'!K5)) -> 8:30 | L5: =IF('Raw Data'!L5="","",'Raw Data'!L5) | M5: =IF('Raw Data'!M5="","",'Raw Data'!M5) -> 20.8 | N5: =IF('Raw Data'!N5="","",IF('Raw Data'!N5="-",0,'Raw Data'!N5)) -> 3.1 | O5: =IF('Raw Data'!O5="",IF('Raw Data'!N5="","",0),'Raw Data'!O5) -> 0 | P5: =IF('Raw Data'!P5="","",'Raw Data'!P5) -> A is at the base of the cable spike on the downstream side of Sump I | Q5: =" " | R5: =IF(ISERROR(FIND(":",G5)),IF(G5<>"-",1*G5,G5),1*LEFT(G5,FIND(":",G5)-1)+RIGHT(G5,LEN(G5)-FIND(":",G5))/60) -> - | S5: =IF(ISERROR(FIND(":",H5)),IF(H5<>"-",1*H5,H5),1*LEFT(H5,FIND(":",H5)-1)+RIGHT(H5,LEN(H5)-FIND(":",H5))/60) -> 103 | T5: =IF(ISERROR(FIND(":",I5)),IF(I5<>"-",1*I5,I5),1*LEFT(I5,FIND(":",I5)-1)+RIGHT(I5,LEN(I5)-FIND(":",I5))/60) -> 283 | U5: =IF(ISERROR(FIND(":",K5)),IF(K5="zero",0,1*K5),1*CONCATENATE(LEFT(K5,FIND(":",K5)-1),".",MID(RIGHT(K5,LEN(K5)-FIND(":",K5))/60,3,8))) -> 8.5 | W5: =J5*COS(U5*PI()/180) -> 20.769333 | X5: =J5*SIN(U5*PI()/180) -> 3.1039976 | Y5: =IF(R5="-",IF(S5>180,S5-180,S5+180),R5) -> 283
A6: =IF('Raw Data'!A6="","",'Raw Data'!A6) -> B | B6: =IF('Raw Data'!B6="","",'Raw Data'!B6) -> C | C6: =IF('Raw Data'!C6="","",'Raw Data'!C6) -> 6 | D6: =IF('Raw Data'!D6="","",'Raw Data'!D6) -> 3.5 | E6: =IF('Raw Data'!E6="","",'Raw Data'!E6) -> 3 | F6: =IF('Raw Data'!F6="","",'Raw Data'!F6) -> 6 | G6: =IF('Raw Data'!G6="/","-",IF('Raw Data'!G6="","-",SUBSTITUTE('Raw Data'!G6," ",":",1))) -> 322:30 | H6: =IF('Raw Data'!H6="/","-",IF('Raw Data'!H6="","-",SUBSTITUTE('Raw Data'!H6," ",":",1))) -> - | I6: =IF('Raw Data'!I6="/","-",IF('Raw Data'!I6="","-",SUBSTITUTE('Raw Data'!I6," ",":",1))) -> 322:30 | J6: =IF('Raw Data'!J6="",IF(LEN(K6)>6,SQRT('Raw Data'!M6^2+N6^2),""),'Raw Data'!J6) -> 27 | K6: =IF('Raw Data'!K6="","",IF(LEN('Raw Data'!K6)<7,SUBSTITUTE('Raw Data'!K6," ",":",1),'Raw Data'!K6)) -> -9:30 | L6: =IF('Raw Data'!L6="","",'Raw Data'!L6) | M6: =IF('Raw Data'!M6="","",'Raw Data'!M6) -> 26.7 | N6: =IF('Raw Data'!N6="","",IF('Raw Data'!N6="-",0,'Raw Data'!N6)) -> -4.5 | O6: =IF('Raw Data'!O6="",IF('Raw Data'!N6="","",0),'Raw Data'!O6) -> 3.1 | P6: =IF('Raw Data'!P6="","",'Raw Data'!P6) -> B is on a rock at upstream end of pool | Q6: =" " | R6: =IF(ISERROR(FIND(":",G6)),IF(G6<>"-",1*G6,G6),1*LEFT(G6,FIND(":",G6)-1)+RIGHT(G6,LEN(G6)-FIND(":",G6))/60) -> 322.5 | S6: =IF(ISERROR(FIND(":",H6)),IF(H6<>"-",1*H6,H6),1*LEFT(H6,FIND(":",H6)-1)+RIGHT(H6,LEN(H6)-FIND(":",H6))/60) -> - | T6: =IF(ISERROR(FIND(":",I6)),IF(I6<>"-",1*I6,I6),1*LEFT(I6,FIND(":",I6)-1)+RIGHT(I6,LEN(I6)-FIND(":",I6))/60) -> 322.5 | U6: =IF(ISERROR(FIND(":",K6)),IF(K6="zero",0,1*K6),1*CONCATENATE(LEFT(K6,FIND(":",K6)-1),".",MID(RIGHT(K6,LEN(K6)-FIND(":",K6))/60,3,8))) -> -9.5 | W6: =J6*COS(U6*PI()/180) -> 26.629711 | X6: =J6*SIN(U6*PI()/180) -> -4.4562854 | Y6: =IF(R6="-",IF(S6>180,S6-180,S6+180),R6) -> 322.5 | Z6: =IF('Raw Data'!O6="","",O5+N5) -> 3.1
A7: =IF('Raw Data'!A7="","",'Raw Data'!A7) -> C | B7: =IF('Raw Data'!B7="","",'Raw Data'!B7) -> D | C7: =IF('Raw Data'!C7="","",'Raw Data'!C7) -> 7 | D7: =IF('Raw Data'!D7="","",'Raw Data'!D7) -> - | E7: =IF('Raw Data'!E7="","",'Raw Data'!E7) -> 4 | F7: =IF('Raw Data'!F7="","",'Raw Data'!F7) -> 2 | G7: =IF('Raw Data'!G7="/","-",IF('Raw Data'!G7="","-",SUBSTITUTE('Raw Data'!G7," ",":",1))) -> - | H7: =IF('Raw Data'!H7="/","-",IF('Raw Data'!H7="","-",SUBSTITUTE('Raw Data'!H7," ",":",1))) -> 83 | I7: =IF('Raw Data'!I7="/","-",IF('Raw Data'!I7="","-",SUBSTITUTE('Raw Data'!I7," ",":",1))) -> 263 | J7: =IF('Raw Data'!J7="",IF(LEN(K7)>6,SQRT('Raw Data'!M7^2+N7^2),""),'Raw Data'!J7) -> 37 | K7: =IF('Raw Data'!K7="","",IF(LEN('Raw Data'!K7)<7,SUBSTITUTE('Raw Data'!K7," ",":",1),'Raw Data'!K7)) -> rise of 1.5 feet | L7: =IF('Raw Data'!L7="","",'Raw Data'!L7) | M7: =IF('Raw Data'!M7="","",'Raw Data'!M7) -> 37 | N7: =IF('Raw Data'!N7="","",IF('Raw Data'!N7="-",0,'Raw Data'!N7)) -> 1.5 | O7: =IF('Raw Data'!O7="",IF('Raw Data'!N7="","",0),'Raw Data'!O7) -> -1.4 | P7: =IF('Raw Data'!P7="","",'Raw Data'!P7) -> C is on edge of pool 10' before Duck I | Q7: =" " | R7: =IF(ISERROR(FIND(":",G7)),IF(G7<>"-",1*G7,G7),1*LEFT(G7,FIND(":",G7)-1)+RIGHT(G7,LEN(G7)-FIND(":",G7))/60) -> - | S7: =IF(ISERROR(FIND(":",H7)),IF(H7<>"-",1*H7,H7),1*LEFT(H7,FIND(":",H7)-1)+RIGHT(H7,LEN(H7)-FIND(":",H7))/60) -> 83 | T7: =IF(ISERROR(FIND(":",I7)),IF(I7<>"-",1*I7,I7),1*LEFT(I7,FIND(":",I7)-1)+RIGHT(I7,LEN(I7)-FIND(":",I7))/60) -> 263 | U7: =ASIN(N7/J7)*180/PI() -> 2.3234386 | W7: =J7*COS(U7*PI()/180) -> 36.969582 | X7: =J7*SIN(U7*PI()/180) -> 1.5 | Y7: =IF(R7="-",IF(S7>180,S7-180,S7+180),R7) -> 263 | Z7: =IF('Raw Data'!O7="","",O6+N6) -> -1.4
A8: =IF('Raw Data'!A8="","",'Raw Data'!A8) -> D | B8: =IF('Raw Data'!B8="","",'Raw Data'!B8) -> E | C8: =IF('Raw Data'!C8="","",'Raw Data'!C8) -> 25 | D8: =IF('Raw Data'!D8="","",'Raw Data'!D8) -> 2 | E8: =IF('Raw Data'!E8="","",'Raw Data'!E8) -> - | F8: =IF('Raw Data'!F8="","",'Raw Data'!F8) -> 10 | G8: =IF('Raw Data'!G8="/","-",IF('Raw Data'!G8="","-",SUBSTITUTE('Raw Data'!G8," ",":",1))) -> 192:30 | H8: =IF('Raw Data'!H8="/","-",IF('Raw Data'!H8="","-",SUBSTITUTE('Raw Data'!H8," ",":",1))) -> - | I8: =IF('Raw Data'!I8="/","-",IF('Raw Data'!I8="","-",SUBSTITUTE('Raw Data'!I8," ",":",1))) -> 192:30 | J8: =IF('Raw Data'!J8="",IF(LEN(K8)>6,SQRT('Raw Data'!M8^2+N8^2),""),'Raw Data'!J8) -> 16.2 | K8: =IF('Raw Data'!K8="","",IF(LEN('Raw Data'!K8)<7,SUBSTITUTE('Raw Data'!K8," ",":",1),'Raw Data'!K8)) -> 4:30 | L8: =IF('Raw Data'!L8="","",'Raw Data'!L8) | M8: =IF('Raw Data'!M8="","",'Raw Data'!M8) -> 16.1 | N8: =IF('Raw Data'!N8="","",IF('Raw Data'!N8="-",0,'Raw Data'!N8)) -> 1.3 | O8: =IF('Raw Data'!O8="",IF('Raw Data'!N8="","",0),'Raw Data'!O8) -> 0.1 | P8: =IF('Raw Data'!P8="","",'Raw Data'!P8) -> D is in stream. Big rock (start of New Series survey) 10' away at 350 (deg). Big passage starts as continuation of Howards Dig. | Q8: =" " | R8: =IF(ISERROR(FIND(":",G8)),IF(G8<>"-",1*G8,G8),1*LEFT(G8,FIND(":",G8)-1)+RIGHT(G8,LEN(G8)-FIND(":",G8))/60) -> 192.5 | S8: =IF(ISERROR(FIND(":",H8)),IF(H8<>"-",1*H8,H8),1*LEFT(H8,FIND(":",H8)-1)+RIGHT(H8,LEN(H8)-FIND(":",H8))/60) -> - | T8: =IF(ISERROR(FIND(":",I8)),IF(I8<>"-",1*I8,I8),1*LEFT(I8,FIND(":",I8)-1)+RIGHT(I8,LEN(I8)-FIND(":",I8))/60) -> 192.5 | U8: =IF(ISERROR(FIND(":",K8)),IF(K8="zero",0,1*K8),1*CONCATENATE(LEFT(K8,FIND(":",K8)-1),".",MID(RIGHT(K8,LEN(K8)-FIND(":",K8))/60,3,8))) -> 4.5 | W8: =J8*COS(U8*PI()/180) -> 16.150061 | X8: =J8*SIN(U8*PI()/180) -> 1.2710374 | Y8: =IF(R8="-",IF(S8>180,S8-180,S8+180),R8) -> 192.5 | Z8: =IF('Raw Data'!O8="","",O7+N7) -> 0.1
A9: =IF('Raw Data'!A9="","",'Raw Data'!A9) -> E | B9: =IF('Raw Data'!B9="","",'Raw Data'!B9) -> F | C9: =IF('Raw Data'!C9="","",'Raw Data'!C9) -> 25 | D9: =IF('Raw Data'!D9="","",'Raw Data'!D9) -> 4.5 | E9: =IF('Raw Data'!E9="","",'Raw Data'!E9) -> 6 | F9: =IF('Raw Data'!F9="","",'Raw Data'!F9) -> - | G9: =IF('Raw Data'!G9="/","-",IF('Raw Data'!G9="","-",SUBSTITUTE('Raw Data'!G9," ",":",1))) -> - | H9: =IF('Raw Data'!H9="/","-",IF('Raw Data'!H9="","-",SUBSTITUTE('Raw Data'!H9," ",":",1))) -> 78 | I9: =IF('Raw Data'!I9="/","-",IF('Raw Data'!I9="","-",SUBSTITUTE('Raw Data'!I9," ",":",1))) -> 258 | J9: =IF('Raw Data'!J9="",IF(LEN(K9)>6,SQRT('Raw Data'!M9^2+N9^2),""),'Raw Data'!J9) -> 47 | K9: =IF('Raw Data'!K9="","",IF(LEN('Raw Data'!K9)<7,SUBSTITUTE('Raw Data'!K9," ",":",1),'Raw Data'!K9)) -> -5:30 | L9: =IF('Raw Data'!L9="","",'Raw Data'!L9) | M9: =IF('Raw Data'!M9="","",'Raw Data'!M9) -> 46.8 | N9: =IF('Raw Data'!N9="","",IF('Raw Data'!N9="-",0,'Raw Data'!N9)) -> -4.5 | O9: =IF('Raw Data'!O9="",IF('Raw Data'!N9="","",0),'Raw Data'!O9) -> 1.4 | P9: =IF('Raw Data'!P9="","",'Raw Data'!P9) | Q9: =" " | R9: =IF(ISERROR(FIND(":",G9)),IF(G9<>"-",1*G9,G9),1*LEFT(G9,FIND(":",G9)-1)+RIGHT(G9,LEN(G9)-FIND(":",G9))/60) -> - | S9: =IF(ISERROR(FIND(":",H9)),IF(H9<>"-",1*H9,H9),1*LEFT(H9,FIND(":",H9)-1)+RIGHT(H9,LEN(H9)-FIND(":",H9))/60) -> 78 | T9: =IF(ISERROR(FIND(":",I9)),IF(I9<>"-",1*I9,I9),1*LEFT(I9,FIND(":",I9)-1)+RIGHT(I9,LEN(I9)-FIND(":",I9))/60) -> 258 | U9: =IF(ISERROR(FIND(":",K9)),IF(K9="zero",0,1*K9),1*CONCATENATE(LEFT(K9,FIND(":",K9)-1),".",MID(RIGHT(K9,LEN(K9)-FIND(":",K9))/60,3,8))) -> -5.5 | W9: =J9*COS(U9*PI()/180) -> 46.783621 | X9: =J9*SIN(U9*PI()/180) -> -4.5047504 | Y9: =IF(R9="-",IF(S9>180,S9-180,S9+180),R9) -> 258 | Z9: =IF('Raw Data'!O9="","",O8+N8) -> 1.4
A10: =IF('Raw Data'!A10="","",'Raw Data'!A10) -> F | B10: =IF('Raw Data'!B10="","",'Raw Data'!B10) -> G | C10: =IF('Raw Data'!C10="","",'Raw Data'!C10) -> 4 | D10: =IF('Raw Data'!D10="","",'Raw Data'!D10) -> 2 | E10: =IF('Raw Data'!E10="","",'Raw Data'!E10) -> 0.5 | F10: =IF('Raw Data'!F10="","",'Raw Data'!F10) -> 3 (30 in B.Place(?)) | G10: =IF('Raw Data'!G10="/","-",IF('Raw Data'!G10="","-",SUBSTITUTE('Raw Data'!G10," ",":",1))) -> 292 | H10: =IF('Raw Data'!H10="/","-",IF('Raw Data'!H10="","-",SUBSTITUTE('Raw Data'!H10," ",":",1))) -> - | I10: =IF('Raw Data'!I10="/","-",IF('Raw Data'!I10="","-",SUBSTITUTE('Raw Data'!I10," ",":",1))) -> 292 | J10: =IF('Raw Data'!J10="",IF(LEN(K10)>6,SQRT('Raw Data'!M10^2+N10^2),""),'Raw Data'!J10) -> 48 | K10: =IF('Raw Data'!K10="","",IF(LEN('Raw Data'!K10)<7,SUBSTITUTE('Raw Data'!K10," ",":",1),'Raw Data'!K10)) -> fall of 2.5 feet | L10: =IF('Raw Data'!L10="","",'Raw Data'!L10) | M10: =IF('Raw Data'!M10="","",'Raw Data'!M10) -> 48 | N10: =IF('Raw Data'!N10="","",IF('Raw Data'!N10="-",0,'Raw Data'!N10)) -> -2.5 | O10: =IF('Raw Data'!O10="",IF('Raw Data'!N10="","",0),'Raw Data'!O10) -> -3.1 | P10: =IF('Raw Data'!P10="","",'Raw Data'!P10) -> At 40' the roof lowers suddenly to Creep I. The big Bedding Plane passage comes in on the right, from -5' to 40' | Q10: =" " | R10: =IF(ISERROR(FIND(":",G10)),IF(G10<>"-",1*G10,G10),1*LEFT(G10,FIND(":",G10)-1)+RIGHT(G10,LEN(G10)-FIND(":",G10))/60) -> 292 | S10: =IF(ISERROR(FIND(":",H10)),IF(H10<>"-",1*H10,H10),1*LEFT(H10,FIND(":",H10)-1)+RIGHT(H10,LEN(H10)-FIND(":",H10))/60) -> - | T10: =IF(ISERROR(FIND(":",I10)),IF(I10<>"-",1*I10,I10),1*LEFT(I10,FIND(":",I10)-1)+RIGHT(I10,LEN(I10)-FIND(":",I10))/60) -> 292 | U10: =ASIN(N10/J10)*180/PI() -> -2.985506 | W10: =J10*COS(U10*PI()/180) -> 47.934852 | X10: =J10*SIN(U10*PI()/180) -> -2.5 | Y10: =IF(R10="-",IF(S10>180,S10-180,S10+180),R10) -> 292 | Z10: =IF('Raw Data'!O10="","",O9+N9) -> -3.1
A11: =IF('Raw Data'!A11="","",'Raw Data'!A11) -> G | B11: =IF('Raw Data'!B11="","",'Raw Data'!B11) -> H | C11: =IF('Raw Data'!C11="","",'Raw Data'!C11) -> 2.5 | D11: =IF('Raw Data'!D11="","",'Raw Data'!D11) -> 0.5 | E11: =IF('Raw Data'!E11="","",'Raw Data'!E11) -> 3.5 | F11: =IF('Raw Data'!F11="","",'Raw Data'!F11) -> 7 | G11: =IF('Raw Data'!G11="/","-",IF('Raw Data'!G11="","-",SUBSTITUTE('Raw Data'!G11," ",":",1))) -> - | H11: =IF('Raw Data'!H11="/","-",IF('Raw Data'!H11="","-",SUBSTITUTE('Raw Data'!H11," ",":",1))) -> 159 | I11: =IF('Raw Data'!I11="/","-",IF('Raw Data'!I11="","-",SUBSTITUTE('Raw Data'!I11," ",":",1))) -> 339 | J11: =IF('Raw Data'!J11="",IF(LEN(K11)>6,SQRT('Raw Data'!M11^2+N11^2),""),'Raw Data'!J11) -> 36 | K11: =IF('Raw Data'!K11="","",IF(LEN('Raw Data'!K11)<7,SUBSTITUTE('Raw Data'!K11," ",":",1),'Raw Data'!K11)) -> level | L11: =IF('Raw Data'!L11="","",'Raw Data'!L11) | M11: =IF('Raw Data'!M11="","",'Raw Data'!M11) -> 36 | N11: =IF('Raw Data'!N11="","",IF('Raw Data'!N11="-",0,'Raw Data'!N11)) -> 0 | O11: =IF('Raw Data'!O11="",IF('Raw Data'!N11="","",0),'Raw Data'!O11) -> -5.6 | P11: =IF('Raw Data'!P11="","",'Raw Data'!P11) | Q11: =" " | R11: =IF(ISERROR(FIND(":",G11)),IF(G11<>"-",1*G11,G11),1*LEFT(G11,FIND(":",G11)-1)+RIGHT(G11,LEN(G11)-FIND(":",G11))/60) -> - | S11: =IF(ISERROR(FIND(":",H11)),IF(H11<>"-",1*H11,H11),1*LEFT(H11,FIND(":",H11)-1)+RIGHT(H11,LEN(H11)-FIND(":",H11))/60) -> 159 | T11: =IF(ISERROR(FIND(":",I11)),IF(I11<>"-",1*I11,I11),1*LEFT(I11,FIND(":",I11)-1)+RIGHT(I11,LEN(I11)-FIND(":",I11))/60) -> 339 | U11: =ASIN(N11/J11)*180/PI() -> 0 | W11: =J11*COS(U11*PI()/180) -> 36 | X11: =J11*SIN(U11*PI()/180) -> 0 | Y11: =IF(R11="-",IF(S11>180,S11-180,S11+180),R11) -> 339 | Z11: =IF('Raw Data'!O11="","",O10+N10) -> -5.6
A12: =IF('Raw Data'!A12="","",'Raw Data'!A12) -> H | B12: =IF('Raw Data'!B12="","",'Raw Data'!B12) -> I | C12: =IF('Raw Data'!C12="","",'Raw Data'!C12) -> 15 | D12: =IF('Raw Data'!D12="","",'Raw Data'!D12) -> 1 | E12: =IF('Raw Data'!E12="","",'Raw Data'!E12) -> 10 | F12: =IF('Raw Data'!F12="","",'Raw Data'!F12) -> 3 | G12: =IF('Raw Data'!G12="/","-",IF('Raw Data'!G12="","-",SUBSTITUTE('Raw Data'!G12," ",":",1))) -> 247 | H12: =IF('Raw Data'!H12="/","-",IF('Raw Data'!H12="","-",SUBSTITUTE('Raw Data'!H12," ",":",1))) -> - | I12: =IF('Raw Data'!I12="/","-",IF('Raw Data'!I12="","-",SUBSTITUTE('Raw Data'!I12," ",":",1))) -> 247 | J12: =IF('Raw Data'!J12="",IF(LEN(K12)>6,SQRT('Raw Data'!M12^2+N12^2),""),'Raw Data'!J12) -> 31 | K12: =IF('Raw Data'!K12="","",IF(LEN('Raw Data'!K12)<7,SUBSTITUTE('Raw Data'!K12," ",":",1),'Raw Data'!K12)) -> -2:30 | L12: =IF('Raw Data'!L12="","",'Raw Data'!L12) | M12: =IF('Raw Data'!M12="","",'Raw Data'!M12) -> 31 | N12: =IF('Raw Data'!N12="","",IF('Raw Data'!N12="-",0,'Raw Data'!N12)) -> -1.3 | O12: =IF('Raw Data'!O12="",IF('Raw Data'!N12="","",0),'Raw Data'!O12) -> -5.6 | P12: =IF('Raw Data'!P12="","",'Raw Data'!P12) | Q12: =" " | R12: =IF(ISERROR(FIND(":",G12)),IF(G12<>"-",1*G12,G12),1*LEFT(G12,FIND(":",G12)-1)+RIGHT(G12,LEN(G12)-FIND(":",G12))/60) -> 247 | S12: =IF(ISERROR(FIND(":",H12)),IF(H12<>"-",1*H12,H12),1*LEFT(H12,FIND(":",H12)-1)+RIGHT(H12,LEN(H12)-FIND(":",H12))/60) -> - | T12: =IF(ISERROR(FIND(":",I12)),IF(I12<>"-",1*I12,I12),1*LEFT(I12,FIND(":",I12)-1)+RIGHT(I12,LEN(I12)-FIND(":",I12))/60) -> 247 | U12: =IF(ISERROR(FIND(":",K12)),IF(K12="zero",0,1*K12),1*CONCATENATE(LEFT(K12,FIND(":",K12)-1),".",MID(RIGHT(K12,LEN(K12)-FIND(":",K12))/60,3,8))) -> -2.5 | W12: =J12*COS(U12*PI()/180) -> 30.970495 | X12: =J12*SIN(U12*PI()/180) -> -1.352201 | Y12: =IF(R12="-",IF(S12>180,S12-180,S12+180),R12) -> 247 | Z12: =IF('Raw Data'!O12="","",O11+N11) -> -5.6
A13: =IF('Raw Data'!A13="","",'Raw Data'!A13) -> I | B13: =IF('Raw Data'!B13="","",'Raw Data'!B13) -> J | C13: =IF('Raw Data'!C13="","",'Raw Data'!C13) -> 15 | D13: =IF('Raw Data'!D13="","",'Raw Data'!D13) -> 1 | E13: =IF('Raw Data'!E13="","",'Raw Data'!E13) -> 8 | F13: =IF('Raw Data'!F13="","",'Raw Data'!F13) -> 2 | G13: =IF('Raw Data'!G13="/","-",IF('Raw Data'!G13="","-",SUBSTITUTE('Raw Data'!G13," ",":",1))) -> - | H13: =IF('Raw Data'!H13="/","-",IF('Raw Data'!H13="","-",SUBSTITUTE('Raw Data'!H13," ",":",1))) -> 95 | I13: =IF('Raw Data'!I13="/","-",IF('Raw Data'!I13="","-",SUBSTITUTE('Raw Data'!I13," ",":",1))) -> 275 | J13: =IF('Raw Data'!J13="",IF(LEN(K13)>6,SQRT('Raw Data'!M13^2+N13^2),""),'Raw Data'!J13) -> 26 | K13: =IF('Raw Data'!K13="","",IF(LEN('Raw Data'!K13)<7,SUBSTITUTE('Raw Data'!K13," ",":",1),'Raw Data'!K13)) -> 2 | L13: =IF('Raw Data'!L13="","",'Raw Data'!L13) | M13: =IF('Raw Data'!M13="","",'Raw Data'!M13) -> 26 | N13: =IF('Raw Data'!N13="","",IF('Raw Data'!N13="-",0,'Raw Data'!N13)) -> 0.9 | O13: =IF('Raw Data'!O13="",IF('Raw Data'!N13="","",0),'Raw Data'!O13) -> -6.9 | P13: =IF('Raw Data'!P13="","",'Raw Data'!P13) | Q13: =" " | R13: =IF(ISERROR(FIND(":",G13)),IF(G13<>"-",1*G13,G13),1*LEFT(G13,FIND(":",G13)-1)+RIGHT(G13,LEN(G13)-FIND(":",G13))/60) -> - | S13: =IF(ISERROR(FIND(":",H13)),IF(H13<>"-",1*H13,H13),1*LEFT(H13,FIND(":",H13)-1)+RIGHT(H13,LEN(H13)-FIND(":",H13))/60) -> 95 | T13: =IF(ISERROR(FIND(":",I13)),IF(I13<>"-",1*I13,I13),1*LEFT(I13,FIND(":",I13)-1)+RIGHT(I13,LEN(I13)-FIND(":",I13))/60) -> 275 | U13: =IF(ISERROR(FIND(":",K13)),IF(K13="zero",0,1*K13),1*CONCATENATE(LEFT(K13,FIND(":",K13)-1),".",MID(RIGHT(K13,LEN(K13)-FIND(":",K13))/60,3,8))) -> 2 | W13: =J13*COS(U13*PI()/180) -> 25.984162 | X13: =J13*SIN(U13*PI()/180) -> 0.90738691 | Y13: =IF(R13="-",IF(S13>180,S13-180,S13+180),R13) -> 275 | Z13: =IF('Raw Data'!O13="","",O12+N12) -> -6.9
A14: =IF('Raw Data'!A14="","",'Raw Data'!A14) -> J | B14: =IF('Raw Data'!B14="","",'Raw Data'!B14) -> K | C14: =IF('Raw Data'!C14="","",'Raw Data'!C14) -> 8 | D14: =IF('Raw Data'!D14="","",'Raw Data'!D14) -> 3 | E14: =IF('Raw Data'!E14="","",'Raw Data'!E14) -> 1 | F14: =IF('Raw Data'!F14="","",'Raw Data'!F14) -> 2 | G14: =IF('Raw Data'!G14="/","-",IF('Raw Data'!G14="","-",SUBSTITUTE('Raw Data'!G14," ",":",1))) -> 320 | H14: =IF('Raw Data'!H14="/","-",IF('Raw Data'!H14="","-",SUBSTITUTE('Raw Data'!H14," ",":",1))) -> - | I14: =IF('Raw Data'!I14="/","-",IF('Raw Data'!I14="","-",SUBSTITUTE('Raw Data'!I14," ",":",1))) -> 320 | J14: =IF('Raw Data'!J14="",IF(LEN(K14)>6,SQRT('Raw Data'!M14^2+N14^2),""),'Raw Data'!J14) -> 26.5 | K14: =IF('Raw Data'!K14="","",IF(LEN('Raw Data'!K14)<7,SUBSTITUTE('Raw Data'!K14," ",":",1),'Raw Data'!K14)) -> 1 | L14: =IF('Raw Data'!L14="","",'Raw Data'!L14) | M14: =IF('Raw Data'!M14="","",'Raw Data'!M14) -> 26.5 | N14: =IF('Raw Data'!N14="","",IF('Raw Data'!N14="-",0,'Raw Data'!N14)) -> 0.5 | O14: =IF('Raw Data'!O14="",IF('Raw Data'!N14="","",0),'Raw Data'!O14) -> -6 | P14: =IF('Raw Data'!P14="","",'Raw Data'!P14) -> Pots | Q14: =" " | R14: =IF(ISERROR(FIND(":",G14)),IF(G14<>"-",1*G14,G14),1*LEFT(G14,FIND(":",G14)-1)+RIGHT(G14,LEN(G14)-FIND(":",G14))/60) -> 320 | S14: =IF(ISERROR(FIND(":",H14)),IF(H14<>"-",1*H14,H14),1*LEFT(H14,FIND(":",H14)-1)+RIGHT(H14,LEN(H14)-FIND(":",H14))/60) -> - | T14: =IF(ISERROR(FIND(":",I14)),IF(I14<>"-",1*I14,I14),1*LEFT(I14,FIND(":",I14)-1)+RIGHT(I14,LEN(I14)-FIND(":",I14))/60) -> 320 | U14: =IF(ISERROR(FIND(":",K14)),IF(K14="zero",0,1*K14),1*CONCATENATE(LEFT(K14,FIND(":",K14)-1),".",MID(RIGHT(K14,LEN(K14)-FIND(":",K14))/60,3,8))) -> 1 | W14: =J14*COS(U14*PI()/180) -> 26.495964 | X14: =J14*SIN(U14*PI()/180) -> 0.46248877 | Y14: =IF(R14="-",IF(S14>180,S14-180,S14+180),R14) -> 320 | Z14: =IF('Raw Data'!O14="","",O13+N13) -> -6
A15: =IF('Raw Data'!A15="","",'Raw Data'!A15) -> K | B15: =IF('Raw Data'!B15="","",'Raw Data'!B15) -> L | C15: =IF('Raw Data'!C15="","",'Raw Data'!C15) -> 25 | D15: =IF('Raw Data'!D15="","",'Raw Data'!D15) -> 4.5 | E15: =IF('Raw Data'!E15="","",'Raw Data'!E15) -> - | F15: =IF('Raw Data'!F15="","",'Raw Data'!F15) -> 4 | G15: =IF('Raw Data'!G15="/","-",IF('Raw Data'!G15="","-",SUBSTITUTE('Raw Data'!G15," ",":",1))) -> - | H15: =IF('Raw Data'!H15="/","-",IF('Raw Data'!H15="","-",SUBSTITUTE('Raw Data'!H15," ",":",1))) -> 193 | I15: =IF('Raw Data'!I15="/","-",IF('Raw Data'!I15="","-",SUBSTITUTE('Raw Data'!I15," ",":",1))) -> 13 | J15: =IF('Raw Data'!J15="",IF(LEN(K15)>6,SQRT('Raw Data'!M15^2+N15^2),""),'Raw Data'!J15) -> 17.5 | K15: =IF('Raw Data'!K15="","",IF(LEN('Raw Data'!K15)<7,SUBSTITUTE('Raw Data'!K15," ",":",1),'Raw Data'!K15)) -> -9 | L15: =IF('Raw Data'!L15="","",'Raw Data'!L15) | M15: =IF('Raw Data'!M15="","",'Raw Data'!M15) -> 17.3 | N15: =IF('Raw Data'!N15="","",IF('Raw Data'!N15="-",0,'Raw Data'!N15)) -> -2.7 | O15: =IF('Raw Data'!O15="",IF('Raw Data'!N15="","",0),'Raw Data'!O15) -> -5.5 | P15: =IF('Raw Data'!P15="","",'Raw Data'!P15) -> Pots | Q15: =" " | R15: =IF(ISERROR(FIND(":",G15)),IF(G15<>"-",1*G15,G15),1*LEFT(G15,FIND(":",G15)-1)+RIGHT(G15,LEN(G15)-FIND(":",G15))/60) -> - | S15: =IF(ISERROR(FIND(":",H15)),IF(H15<>"-",1*H15,H15),1*LEFT(H15,FIND(":",H15)-1)+RIGHT(H15,LEN(H15)-FIND(":",H15))/60) -> 193 | T15: =IF(ISERROR(FIND(":",I15)),IF(I15<>"-",1*I15,I15),1*LEFT(I15,FIND(":",I15)-1)+RIGHT(I15,LEN(I15)-FIND(":",I15))/60) -> 13 | U15: =IF(ISERROR(FIND(":",K15)),IF(K15="zero",0,1*K15),1*CONCATENATE(LEFT(K15,FIND(":",K15)-1),".",MID(RIGHT(K15,LEN(K15)-FIND(":",K15))/60,3,8))) -> -9 | W15: =J15*COS(U15*PI()/180) -> 17.284546 | X15: =J15*SIN(U15*PI()/180) -> -2.7376031 | Y15: =IF(R15="-",IF(S15>180,S15-180,S15+180),R15) -> 13 | Z15: =IF('Raw Data'!O15="","",O14+N14) -> -5.5
A16: =IF('Raw Data'!A16="","",'Raw Data'!A16) -> L | B16: =IF('Raw Data'!B16="","",'Raw Data'!B16) -> M | C16: =IF('Raw Data'!C16="","",'Raw Data'!C16) -> 20 | D16: =IF('Raw Data'!D16="","",'Raw Data'!D16) -> 3 | E16: =IF('Raw Data'!E16="","",'Raw Data'!E16) -> 2 | F16: =IF('Raw Data'!F16="","",'Raw Data'!F16) -> 2 | G16: =IF('Raw Data'!G16="/","-",IF('Raw Data'!G16="","-",SUBSTITUTE('Raw Data'!G16," ",":",1))) -> 299 | H16: =IF('Raw Data'!H16="/","-",IF('Raw Data'!H16="","-",SUBSTITUTE('Raw Data'!H16," ",":",1))) -> - | I16: =IF('Raw Data'!I16="/","-",IF('Raw Data'!I16="","-",SUBSTITUTE('Raw Data'!I16," ",":",1))) -> 299 | J16: =IF('Raw Data'!J16="",IF(LEN(K16)>6,SQRT('Raw Data'!M16^2+N16^2),""),'Raw Data'!J16) -> 33 | K16: =IF('Raw Data'!K16="","",IF(LEN('Raw Data'!K16)<7,SUBSTITUTE('Raw Data'!K16," ",":",1),'Raw Data'!K16)) -> -3 | L16: =IF('Raw Data'!L16="","",'Raw Data'!L16) | M16: =IF('Raw Data'!M16="","",'Raw Data'!M16) -> 33 | N16: =IF('Raw Data'!N16="","",IF('Raw Data'!N16="-",0,'Raw Data'!N16)) -> -1.7 | O16: =IF('Raw Data'!O16="",IF('Raw Data'!N16="","",0),'Raw Data'!O16) -> -8.2 | P16: =IF('Raw Data'!P16="","",'Raw Data'!P16) -> L is at foot of climb to Approach passage. Clay fill remains 6' up on left wall. | Q16: =" " | R16: =IF(ISERROR(FIND(":",G16)),IF(G16<>"-",1*G16,G16),1*LEFT(G16,FIND(":",G16)-1)+RIGHT(G16,LEN(G16)-FIND(":",G16))/60) -> 299 | S16: =IF(ISERROR(FIND(":",H16)),IF(H16<>"-",1*H16,H16),1*LEFT(H16,FIND(":",H16)-1)+RIGHT(H16,LEN(H16)-FIND(":",H16))/60) -> - | T16: =IF(ISERROR(FIND(":",I16)),IF(I16<>"-",1*I16,I16),1*LEFT(I16,FIND(":",I16)-1)+RIGHT(I16,LEN(I16)-FIND(":",I16))/60) -> 299 | U16: =IF(ISERROR(FIND(":",K16)),IF(K16="zero",0,1*K16),1*CONCATENATE(LEFT(K16,FIND(":",K16)-1),".",MID(RIGHT(K16,LEN(K16)-FIND(":",K16))/60,3,8))) -> -3 | W16: =J16*COS(U16*PI()/180) -> 32.954775 | X16: =J16*SIN(U16*PI()/180) -> -1.7270866 | Y16: =IF(R16="-",IF(S16>180,S16-180,S16+180),R16) -> 299 | Z16: =IF('Raw Data'!O16="","",O15+N15) -> -8.2
A17: =IF('Raw Data'!A17="","",'Raw Data'!A17) -> M | B17: =IF('Raw Data'!B17="","",'Raw Data'!B17) -> N | C17: =IF('Raw Data'!C17="","",'Raw Data'!C17) -> 15 | D17: =IF('Raw Data'!D17="","",'Raw Data'!D17) -> 7 | E17: =IF('Raw Data'!E17="","",'Raw Data'!E17) -> 4 | F17: =IF('Raw Data'!F17="","",'Raw Data'!F17) -> - | G17: =IF('Raw Data'!G17="/","-",IF('Raw Data'!G17="","-",SUBSTITUTE('Raw Data'!G17," ",":",1))) -> - | H17: =IF('Raw Data'!H17="/","-",IF('Raw Data'!H17="","-",SUBSTITUTE('Raw Data'!H17," ",":",1))) -> 142 | I17: =IF('Raw Data'!I17="/","-",IF('Raw Data'!I17="","-",SUBSTITUTE('Raw Data'!I17," ",":",1))) -> 322 | J17: =IF('Raw Data'!J17="",IF(LEN(K17)>6,SQRT('Raw Data'!M17^2+N17^2),""),'Raw Data'!J17) -> 43 | K17: =IF('Raw Data'!K17="","",IF(LEN('Raw Data'!K17)<7,SUBSTITUTE('Raw Data'!K17," ",":",1),'Raw Data'!K17)) -> -7.3 | L17: =IF('Raw Data'!L17="","",'Raw Data'!L17) | M17: =IF('Raw Data'!M17="","",'Raw Data'!M17) -> 42.7 | N17: =IF('Raw Data'!N17="","",IF('Raw Data'!N17="-",0,'Raw Data'!N17)) -> -5.6 | O17: =IF('Raw Data'!O17="",IF('Raw Data'!N17="","",0),'Raw Data'!O17) -> -9.9 | P17: =IF('Raw Data'!P17="","",'Raw Data'!P17) -> Pots | Q17: =" " | R17: =IF(ISERROR(FIND(":",G17)),IF(G17<>"-",1*G17,G17),1*LEFT(G17,FIND(":",G17)-1)+RIGHT(G17,LEN(G17)-FIND(":",G17))/60) -> - | S17: =IF(ISERROR(FIND(":",H17)),IF(H17<>"-",1*H17,H17),1*LEFT(H17,FIND(":",H17)-1)+RIGHT(H17,LEN(H17)-FIND(":",H17))/60) -> 142 | T17: =IF(ISERROR(FIND(":",I17)),IF(I17<>"-",1*I17,I17),1*LEFT(I17,FIND(":",I17)-1)+RIGHT(I17,LEN(I17)-FIND(":",I17))/60) -> 322 | U17: =IF(ISERROR(FIND(":",K17)),IF(K17="zero",0,1*K17),1*CONCATENATE(LEFT(K17,FIND(":",K17)-1),".",MID(RIGHT(K17,LEN(K17)-FIND(":",K17))/60,3,8))) -> -7.3 | W17: =J17*COS(U17*PI()/180) -> 42.651461 | X17: =J17*SIN(U17*PI()/180) -> -5.4637782 | Y17: =IF(R17="-",IF(S17>180,S17-180,S17+180),R17) -> 322 | Z17: =IF('Raw Data'!O17="","",O16+N16) -> -9.9
A18: =IF('Raw Data'!A18="","",'Raw Data'!A18) -> N | B18: =IF('Raw Data'!B18="","",'Raw Data'!B18) -> O | C18: =IF('Raw Data'!C18="","",'Raw Data'!C18) -> 25 | D18: =IF('Raw Data'!D18="","",'Raw Data'!D18) -> 3 | E18: =IF('Raw Data'!E18="","",'Raw Data'!E18) -> 2 | F18: =IF('Raw Data'!F18="","",'Raw Data'!F18) -> 1 | G18: =IF('Raw Data'!G18="/","-",IF('Raw Data'!G18="","-",SUBSTITUTE('Raw Data'!G18," ",":",1))) -> 281 | H18: =IF('Raw Data'!H18="/","-",IF('Raw Data'!H18="","-",SUBSTITUTE('Raw Data'!H18," ",":",1))) -> - | I18: =IF('Raw Data'!I18="/","-",IF('Raw Data'!I18="","-",SUBSTITUTE('Raw Data'!I18," ",":",1))) -> 281 | J18: =IF('Raw Data'!J18="",IF(LEN(K18)>6,SQRT('Raw Data'!M18^2+N18^2),""),'Raw Data'!J18) -> 15.5 | K18: =IF('Raw Data'!K18="","",IF(LEN('Raw Data'!K18)<7,SUBSTITUTE('Raw Data'!K18," ",":",1),'Raw Data'!K18)) -> -2 | L18: =IF('Raw Data'!L18="","",'Raw Data'!L18) | M18: =IF('Raw Data'!M18="","",'Raw Data'!M18) -> 15.5 | N18: =IF('Raw Data'!N18="","",IF('Raw Data'!N18="-",0,'Raw Data'!N18)) -> -0.5 | O18: =IF('Raw Data'!O18="",IF('Raw Data'!N18="","",0),'Raw Data'!O18) -> -15.5 | P18: =IF('Raw Data'!P18="","",'Raw Data'!P18) -> Pots | Q18: =" " | R18: =IF(ISERROR(FIND(":",G18)),IF(G18<>"-",1*G18,G18),1*LEFT(G18,FIND(":",G18)-1)+RIGHT(G18,LEN(G18)-FIND(":",G18))/60) -> 281 | S18: =IF(ISERROR(FIND(":",H18)),IF(H18<>"-",1*H18,H18),1*LEFT(H18,FIND(":",H18)-1)+RIGHT(H18,LEN(H18)-FIND(":",H18))/60) -> - | T18: =IF(ISERROR(FIND(":",I18)),IF(I18<>"-",1*I18,I18),1*LEFT(I18,FIND(":",I18)-1)+RIGHT(I18,LEN(I18)-FIND(":",I18))/60) -> 281 | U18: =IF(ISERROR(FIND(":",K18)),IF(K18="zero",0,1*K18),1*CONCATENATE(LEFT(K18,FIND(":",K18)-1),".",MID(RIGHT(K18,LEN(K18)-FIND(":",K18))/60,3,8))) -> -2 | W18: =J18*COS(U18*PI()/180) -> 15.490558 | X18: =J18*SIN(U18*PI()/180) -> -0.5409422 | Y18: =IF(R18="-",IF(S18>180,S18-180,S18+180),R18) -> 281 | Z18: =IF('Raw Data'!O18="","",O17+N17) -> -15.5
A19: =IF('Raw Data'!A19="","",'Raw Data'!A19) -> O | B19: =IF('Raw Data'!B19="","",'Raw Data'!B19) -> P | C19: =IF('Raw Data'!C19="","",'Raw Data'!C19) -> 40 | D19: =IF('Raw Data'!D19="","",'Raw Data'!D19) -> 4.5 | E19: =IF('Raw Data'!E19="","",'Raw Data'!E19) -> 2 | F19: =IF('Raw Data'!F19="","",'Raw Data'!F19) -> 2 | G19: =IF('Raw Data'!G19="/","-",IF('Raw Data'!G19="","-",SUBSTITUTE('Raw Data'!G19," ",":",1))) -> - | H19: =IF('Raw Data'!H19="/","-",IF('Raw Data'!H19="","-",SUBSTITUTE('Raw Data'!H19," ",":",1))) -> 127 | I19: =IF('Raw Data'!I19="/","-",IF('Raw Data'!I19="","-",SUBSTITUTE('Raw Data'!I19," ",":",1))) -> 307 | J19: =IF('Raw Data'!J19="",IF(LEN(K19)>6,SQRT('Raw Data'!M19^2+N19^2),""),'Raw Data'!J19) -> 56 | K19: =IF('Raw Data'!K19="","",IF(LEN('Raw Data'!K19)<7,SUBSTITUTE('Raw Data'!K19," ",":",1),'Raw Data'!K19)) -> -5 | L19: =IF('Raw Data'!L19="","",'Raw Data'!L19) | M19: =IF('Raw Data'!M19="","",'Raw Data'!M19) -> 55.8 | N19: =IF('Raw Data'!N19="","",IF('Raw Data'!N19="-",0,'Raw Data'!N19)) -> -4.9 | O19: =IF('Raw Data'!O19="",IF('Raw Data'!N19="","",0),'Raw Data'!O19) -> -16 | P19: =IF('Raw Data'!P19="","",'Raw Data'!P19) -> Pots. Very pretty coral on left wall | Q19: =" " | R19: =IF(ISERROR(FIND(":",G19)),IF(G19<>"-",1*G19,G19),1*LEFT(G19,FIND(":",G19)-1)+RIGHT(G19,LEN(G19)-FIND(":",G19))/60) -> - | S19: =IF(ISERROR(FIND(":",H19)),IF(H19<>"-",1*H19,H19),1*LEFT(H19,FIND(":",H19)-1)+RIGHT(H19,LEN(H19)-FIND(":",H19))/60) -> 127 | T19: =IF(ISERROR(FIND(":",I19)),IF(I19<>"-",1*I19,I19),1*LEFT(I19,FIND(":",I19)-1)+RIGHT(I19,LEN(I19)-FIND(":",I19))/60) -> 307 | U19: =IF(ISERROR(FIND(":",K19)),IF(K19="zero",0,1*K19),1*CONCATENATE(LEFT(K19,FIND(":",K19)-1),".",MID(RIGHT(K19,LEN(K19)-FIND(":",K19))/60,3,8))) -> -5 | W19: =J19*COS(U19*PI()/180) -> 55.786903 | X19: =J19*SIN(U19*PI()/180) -> -4.8807216 | Y19: =IF(R19="-",IF(S19>180,S19-180,S19+180),R19) -> 307 | Z19: =IF('Raw Data'!O19="","",O18+N18) -> -16
A20: =IF('Raw Data'!A20="","",'Raw Data'!A20) -> P | B20: =IF('Raw Data'!B20="","",'Raw Data'!B20) -> Q | C20: =IF('Raw Data'!C20="","",'Raw Data'!C20) -> 40 | D20: =IF('Raw Data'!D20="","",'Raw Data'!D20) -> 3 | E20: =IF('Raw Data'!E20="","",'Raw Data'!E20) -> 2 | F20: =IF('Raw Data'!F20="","",'Raw Data'!F20) -> 3 | G20: =IF('Raw Data'!G20="/","-",IF('Raw Data'!G20="","-",SUBSTITUTE('Raw Data'!G20," ",":",1))) -> 283 | H20: =IF('Raw Data'!H20="/","-",IF('Raw Data'!H20="","-",SUBSTITUTE('Raw Data'!H20," ",":",1))) -> - | I20: =IF('Raw Data'!I20="/","-",IF('Raw Data'!I20="","-",SUBSTITUTE('Raw Data'!I20," ",":",1))) -> 283 | J20: =IF('Raw Data'!J20="",IF(LEN(K20)>6,SQRT('Raw Data'!M20^2+N20^2),""),'Raw Data'!J20) -> 15.8 | K20: =IF('Raw Data'!K20="","",IF(LEN('Raw Data'!K20)<7,SUBSTITUTE('Raw Data'!K20," ",":",1),'Raw Data'!K20)) -> -0:15 | L20: =IF('Raw Data'!L20="","",'Raw Data'!L20) | M20: =IF('Raw Data'!M20="","",'Raw Data'!M20) -> 15.8 | N20: =IF('Raw Data'!N20="","",IF('Raw Data'!N20="-",0,'Raw Data'!N20)) -> -0.1 | O20: =IF('Raw Data'!O20="",IF('Raw Data'!N20="","",0),'Raw Data'!O20) -> -20.9 | P20: =IF('Raw Data'!P20="","",'Raw Data'!P20) | Q20: =" " | R20: =IF(ISERROR(FIND(":",G20)),IF(G20<>"-",1*G20,G20),1*LEFT(G20,FIND(":",G20)-1)+RIGHT(G20,LEN(G20)-FIND(":",G20))/60) -> 283 | S20: =IF(ISERROR(FIND(":",H20)),IF(H20<>"-",1*H20,H20),1*LEFT(H20,FIND(":",H20)-1)+RIGHT(H20,LEN(H20)-FIND(":",H20))/60) -> - | T20: =IF(ISERROR(FIND(":",I20)),IF(I20<>"-",1*I20,I20),1*LEFT(I20,FIND(":",I20)-1)+RIGHT(I20,LEN(I20)-FIND(":",I20))/60) -> 283 | U20: =ASIN(N20/J20)*180/PI() -> -0.36263394 | W20: =J20*COS(U20*PI()/180) -> 15.799684 | X20: =J20*SIN(U20*PI()/180) -> -0.1 | Y20: =IF(R20="-",IF(S20>180,S20-180,S20+180),R20) -> 283 | Z20: =IF('Raw Data'!O20="","",O19+N19) -> -20.9
A21: =IF('Raw Data'!A21="","",'Raw Data'!A21) -> Q | B21: =IF('Raw Data'!B21="","",'Raw Data'!B21) -> R | C21: =IF('Raw Data'!C21="","",'Raw Data'!C21) -> 40 | D21: =IF('Raw Data'!D21="","",'Raw Data'!D21) -> 4 | E21: =IF('Raw Data'!E21="","",'Raw Data'!E21) -> 4 | F21: =IF('Raw Data'!F21="","",'Raw Data'!F21) -> - | G21: =IF('Raw Data'!G21="/","-",IF('Raw Data'!G21="","-",SUBSTITUTE('Raw Data'!G21," ",":",1))) -> - | H21: =IF('Raw Data'!H21="/","-",IF('Raw Data'!H21="","-",SUBSTITUTE('Raw Data'!H21," ",":",1))) -> 37 | I21: =IF('Raw Data'!I21="/","-",IF('Raw Data'!I21="","-",SUBSTITUTE('Raw Data'!I21," ",":",1))) -> 217 | J21: =IF(LEN(K21)>6,SQRT('Raw Data'!M21^2+N21^2),'Raw Data'!J21) -> 15.814234 | K21: =IF('Raw Data'!K21="","",IF(LEN('Raw Data'!K21)<7,SUBSTITUTE('Raw Data'!K21," ",":",1),'Raw Data'!K21)) -> fall of 4 feet | L21: =IF('Raw Data'!L21="","",'Raw Data'!L21) | M21: =IF('Raw Data'!M21="","",'Raw Data'!M21) -> 15.3 | N21: =IF('Raw Data'!N21="","",IF('Raw Data'!N21="-",0,'Raw Data'!N21)) -> -4 | O21: =IF('Raw Data'!O21="",IF('Raw Data'!N21="","",0),'Raw Data'!O21) -> -21 | P21: =IF('Raw Data'!P21="","",'Raw Data'!P21) -> 1.5 foot deep pool starts at P. | Q21: =" " | R21: =IF(ISERROR(FIND(":",G21)),IF(G21<>"-",1*G21,G21),1*LEFT(G21,FIND(":",G21)-1)+RIGHT(G21,LEN(G21)-FIND(":",G21))/60) -> - | S21: =IF(ISERROR(FIND(":",H21)),IF(H21<>"-",1*H21,H21),1*LEFT(H21,FIND(":",H21)-1)+RIGHT(H21,LEN(H21)-FIND(":",H21))/60) -> 37 | T21: =IF(ISERROR(FIND(":",I21)),IF(I21<>"-",1*I21,I21),1*LEFT(I21,FIND(":",I21)-1)+RIGHT(I21,LEN(I21)-FIND(":",I21))/60) -> 217 | U21: =ASIN(N21/J21)*180/PI() -> -14.651359 | W21: =J21*COS(U21*PI()/180) -> 15.3 | X21: =J21*SIN(U21*PI()/180) -> -4 | Y21: =IF(R21="-",IF(S21>180,S21-180,S21+180),R21) -> 217 | Z21: =IF('Raw Data'!O21="","",O20+N20) -> -21
A22: =IF('Raw Data'!A22="","",'Raw Data'!A22) -> R | B22: =IF('Raw Data'!B22="","",'Raw Data'!B22) -> S | C22: =IF('Raw Data'!C22="","",'Raw Data'!C22) -> 40 | D22: =IF('Raw Data'!D22="","",'Raw Data'!D22) -> - | E22: =IF('Raw Data'!E22="","",'Raw Data'!E22) -> - | F22: =IF('Raw Data'!F22="","",'Raw Data'!F22) -> 4 | G22: =IF('Raw Data'!G22="/","-",IF('Raw Data'!G22="","-",SUBSTITUTE('Raw Data'!G22," ",":",1))) -> 310 | H22: =IF('Raw Data'!H22="/","-",IF('Raw Data'!H22="","-",SUBSTITUTE('Raw Data'!H22," ",":",1))) -> - | I22: =IF('Raw Data'!I22="/","-",IF('Raw Data'!I22="","-",SUBSTITUTE('Raw Data'!I22," ",":",1))) -> 310 | J22: =IF(LEN(K22)>6,SQRT('Raw Data'!M22^2+N22^2),'Raw Data'!J22) -> 39.702015 | K22: =IF('Raw Data'!K22="","",IF(LEN('Raw Data'!K22)<7,SUBSTITUTE('Raw Data'!K22," ",":",1),'Raw Data'!K22)) -> rise of 4 feet | L22: =IF('Raw Data'!L22="","",'Raw Data'!L22) | M22: =IF('Raw Data'!M22="","",'Raw Data'!M22) -> 39.5 | N22: =IF('Raw Data'!N22="","",IF('Raw Data'!N22="-",0,'Raw Data'!N22)) -> 4 | O22: =IF('Raw Data'!O22="",IF('Raw Data'!N22="","",0),'Raw Data'!O22) -> -25 | P22: =IF('Raw Data'!P22="","",'Raw Data'!P22) -> Pool 2.5' deep at R, ends 15' on. Scalloping as in Goughs 1st Sandy Chamber. | Q22: =" " | R22: =IF(ISERROR(FIND(":",G22)),IF(G22<>"-",1*G22,G22),1*LEFT(G22,FIND(":",G22)-1)+RIGHT(G22,LEN(G22)-FIND(":",G22))/60) -> 310 | S22: =IF(ISERROR(FIND(":",H22)),IF(H22<>"-",1*H22,H22),1*LEFT(H22,FIND(":",H22)-1)+RIGHT(H22,LEN(H22)-FIND(":",H22))/60) -> - | T22: =IF(ISERROR(FIND(":",I22)),IF(I22<>"-",1*I22,I22),1*LEFT(I22,FIND(":",I22)-1)+RIGHT(I22,LEN(I22)-FIND(":",I22))/60) -> 310 | U22: =ASIN(N22/J22)*180/PI() -> 5.7823923 | W22: =J22*COS(U22*PI()/180) -> 39.5 | X22: =J22*SIN(U22*PI()/180) -> 4 | Y22: =IF(R22="-",IF(S22>180,S22-180,S22+180),R22) -> 310 | Z22: =IF('Raw Data'!O22="","",O21+N21) -> -25
A23: =IF('Raw Data'!A23="","",'Raw Data'!A23) -> S | B23: =IF('Raw Data'!B23="","",'Raw Data'!B23) -> T | C23: =IF('Raw Data'!C23="","",'Raw Data'!C23) -> 12 | D23: =IF('Raw Data'!D23="","",'Raw Data'!D23) -> 4.5 | E23: =IF('Raw Data'!E23="","",'Raw Data'!E23) -> 8 | F23: =IF('Raw Data'!F23="","",'Raw Data'!F23) -> - | G23: =IF('Raw Data'!G23="/","-",IF('Raw Data'!G23="","-",SUBSTITUTE('Raw Data'!G23," ",":",1))) -> - | H23: =IF('Raw Data'!H23="/","-",IF('Raw Data'!H23="","-",SUBSTITUTE('Raw Data'!H23," ",":",1))) -> 58 | I23: =IF('Raw Data'!I23="/","-",IF('Raw Data'!I23="","-",SUBSTITUTE('Raw Data'!I23," ",":",1))) -> 238 | J23: =IF('Raw Data'!J23="",IF(LEN(K23)>6,SQRT('Raw Data'!M23^2+N23^2),""),'Raw Data'!J23) -> 39.6 | K23: =IF('Raw Data'!K23="","",IF(LEN('Raw Data'!K23)<7,SUBSTITUTE('Raw Data'!K23," ",":",1),'Raw Data'!K23)) -> -2:30 | L23: =IF('Raw Data'!L23="","",'Raw Data'!L23) | M23: =IF('Raw Data'!M23="","",'Raw Data'!M23) -> 39.6 | N23: =IF('Raw Data'!N23="","",IF('Raw Data'!N23="-",0,'Raw Data'!N23)) -> -1.9 | O23: =IF('Raw Data'!O23="",IF('Raw Data'!N23="","",0),'Raw Data'!O23) -> -21 | P23: =IF('Raw Data'!P23="","",'Raw Data'!P23) -> S is marked on wall. At 20' there is a muddy chamber overhead. | Q23: =" " | R23: =IF(ISERROR(FIND(":",G23)),IF(G23<>"-",1*G23,G23),1*LEFT(G23,FIND(":",G23)-1)+RIGHT(G23,LEN(G23)-FIND(":",G23))/60) -> - | S23: =IF(ISERROR(FIND(":",H23)),IF(H23<>"-",1*H23,H23),1*LEFT(H23,FIND(":",H23)-1)+RIGHT(H23,LEN(H23)-FIND(":",H23))/60) -> 58 | T23: =IF(ISERROR(FIND(":",I23)),IF(I23<>"-",1*I23,I23),1*LEFT(I23,FIND(":",I23)-1)+RIGHT(I23,LEN(I23)-FIND(":",I23))/60) -> 238 | U23: =IF(ISERROR(FIND(":",K23)),IF(K23="zero",0,1*K23),1*CONCATENATE(LEFT(K23,FIND(":",K23)-1),".",MID(RIGHT(K23,LEN(K23)-FIND(":",K23))/60,3,8))) -> -2.5 | W23: =J23*COS(U23*PI()/180) -> 39.56231 | X23: =J23*SIN(U23*PI()/180) -> -1.7273277 | Y23: =IF(R23="-",IF(S23>180,S23-180,S23+180),R23) -> 238 | Z23: =IF('Raw Data'!O23="","",O22+N22) -> -21
A24: =IF('Raw Data'!A24="","",'Raw Data'!A24) -> T | B24: =IF('Raw Data'!B24="","",'Raw Data'!B24) -> U | C24: =IF('Raw Data'!C24="","",'Raw Data'!C24) -> 2 | D24: =IF('Raw Data'!D24="","",'Raw Data'!D24) -> 2.5 | E24: =IF('Raw Data'!E24="","",'Raw Data'!E24) -> 15 | F24: =IF('Raw Data'!F24="","",'Raw Data'!F24) -> 6 | G24: =IF('Raw Data'!G24="/","-",IF('Raw Data'!G24="","-",SUBSTITUTE('Raw Data'!G24," ",":",1))) -> 148 | H24: =IF('Raw Data'!H24="/","-",IF('Raw Data'!H24="","-",SUBSTITUTE('Raw Data'!H24," ",":",1))) -> - | I24: =IF('Raw Data'!I24="/","-",IF('Raw Data'!I24="","-",SUBSTITUTE('Raw Data'!I24," ",":",1))) -> 148 | J24: =IF('Raw Data'!J24="",IF(LEN(K24)>6,SQRT('Raw Data'!M24^2+N24^2),""),'Raw Data'!J24) -> 49 | K24: =IF('Raw Data'!K24="","",IF(LEN('Raw Data'!K24)<7,SUBSTITUTE('Raw Data'!K24," ",":",1),'Raw Data'!K24)) -> fall of 1.7 feet | L24: =IF('Raw Data'!L24="","",'Raw Data'!L24) | M24: =IF('Raw Data'!M24="","",'Raw Data'!M24) -> 49 | N24: =IF('Raw Data'!N24="","",IF('Raw Data'!N24="-",0,'Raw Data'!N24)) -> -1.7 | O24: =IF('Raw Data'!O24="",IF('Raw Data'!N24="","",0),'Raw Data'!O24) -> -22.9 | P24: =IF('Raw Data'!P24="","",'Raw Data'!P24) | Q24: =" " | R24: =IF(ISERROR(FIND(":",G24)),IF(G24<>"-",1*G24,G24),1*LEFT(G24,FIND(":",G24)-1)+RIGHT(G24,LEN(G24)-FIND(":",G24))/60) -> 148 | S24: =IF(ISERROR(FIND(":",H24)),IF(H24<>"-",1*H24,H24),1*LEFT(H24,FIND(":",H24)-1)+RIGHT(H24,LEN(H24)-FIND(":",H24))/60) -> - | T24: =IF(ISERROR(FIND(":",I24)),IF(I24<>"-",1*I24,I24),1*LEFT(I24,FIND(":",I24)-1)+RIGHT(I24,LEN(I24)-FIND(":",I24))/60) -> 148 | U24: =ASIN(N24/J24)*180/PI() -> -1.9882118 | W24: =J24*COS(U24*PI()/180) -> 48.970501 | X24: =J24*SIN(U24*PI()/180) -> -1.7 | Y24: =IF(R24="-",IF(S24>180,S24-180,S24+180),R24) -> 148 | Z24: =IF('Raw Data'!O24="","",O23+N23) -> -22.9
A25: =IF('Raw Data'!A25="","",'Raw Data'!A25) -> U | B25: =IF('Raw Data'!B25="","",'Raw Data'!B25) | C25: =IF('Raw Data'!C25="","",'Raw Data'!C25) -> 1.5 | D25: =IF('Raw Data'!D25="","",'Raw Data'!D25) -> 1.5 | E25: =IF('Raw Data'!E25="","",'Raw Data'!E25) | F25: =IF('Raw Data'!F25="","",'Raw Data'!F25) | G25: =IF('Raw Data'!G25="/","-",IF('Raw Data'!G25="","-",SUBSTITUTE('Raw Data'!G25," ",":",1))) -> - | H25: =IF('Raw Data'!H25="/","-",IF('Raw Data'!H25="","-",SUBSTITUTE('Raw Data'!H25," ",":",1))) -> - | I25: =IF('Raw Data'!I25="/","-",IF('Raw Data'!I25="","-",SUBSTITUTE('Raw Data'!I25," ",":",1))) -> - | J25: =IF('Raw Data'!J25="",IF(LEN(K25)>6,SQRT('Raw Data'!M25^2+N25^2),""),'Raw Data'!J25) | K25: =IF('Raw Data'!K25="","",IF(LEN('Raw Data'!K25)<7,SUBSTITUTE('Raw Data'!K25," ",":",1),'Raw Data'!K25)) | L25: =IF('Raw Data'!L25="","",'Raw Data'!L25) | M25: =IF('Raw Data'!M25="","",'Raw Data'!M25) | N25: =IF('Raw Data'!N25="","",IF('Raw Data'!N25="-",0,'Raw Data'!N25)) | O25: =IF('Raw Data'!O25="",IF('Raw Data'!N25="","",0),'Raw Data'!O25) -> -24.6 | P25: =IF('Raw Data'!P25="","",'Raw Data'!P25) -> Beasts (or Pearls? Not clear in scan) seen here. Total = 650' | Q25: =" " | Y25: =IF(R25="-",IF(S25>180,S25-180,S25+180),R25) -> 0 | Z25: =IF('Raw Data'!O25="","",O24+N24) -> -24.6
A26: =IF('Raw Data'!A26="","",'Raw Data'!A26) -> A1 | B26: =IF('Raw Data'!B26="","",'Raw Data'!B26) -> B1 | C26: =IF('Raw Data'!C26="","",'Raw Data'!C26) -> - | D26: =IF('Raw Data'!D26="","",'Raw Data'!D26) -> 1 | E26: =IF('Raw Data'!E26="","",'Raw Data'!E26) -> 1 | F26: =IF('Raw Data'!F26="","",'Raw Data'!F26) -> 0.5 | G26: =IF('Raw Data'!G26="/","-",IF('Raw Data'!G26="","-",SUBSTITUTE('Raw Data'!G26," ",":",1))) -> - | H26: =IF('Raw Data'!H26="/","-",IF('Raw Data'!H26="","-",SUBSTITUTE('Raw Data'!H26," ",":",1))) -> 326 | I26: =IF('Raw Data'!I26="/","-",IF('Raw Data'!I26="","-",SUBSTITUTE('Raw Data'!I26," ",":",1))) -> 146 | J26: =IF('Raw Data'!J26="",IF(LEN(K26)>6,SQRT('Raw Data'!M26^2+N26^2),""),'Raw Data'!J26) -> 30.4 | K26: =IF('Raw Data'!K26="","",IF(LEN('Raw Data'!K26)<7,SUBSTITUTE('Raw Data'!K26," ",":",1),'Raw Data'!K26)) -> level | L26: =IF('Raw Data'!L26="","",'Raw Data'!L26) | M26: =IF('Raw Data'!M26="","",'Raw Data'!M26) -> 30.4 | N26: =IF('Raw Data'!N26="","",IF('Raw Data'!N26="-",0,'Raw Data'!N26)) -> 0 | O26: =IF('Raw Data'!O26="",IF('Raw Data'!N26="","",0),'Raw Data'!O26) -> 0 | P26: =IF('Raw Data'!P26="","",'Raw Data'!P26) -> A1 is far end of "Priddy Green" passage. At choke | Q26: =" " | R26: =IF(ISERROR(FIND(":",G26)),IF(G26<>"-",1*G26,G26),1*LEFT(G26,FIND(":",G26)-1)+RIGHT(G26,LEN(G26)-FIND(":",G26))/60) -> - | S26: =IF(ISERROR(FIND(":",H26)),IF(H26<>"-",1*H26,H26),1*LEFT(H26,FIND(":",H26)-1)+RIGHT(H26,LEN(H26)-FIND(":",H26))/60) -> 326 | T26: =IF(ISERROR(FIND(":",I26)),IF(I26<>"-",1*I26,I26),1*LEFT(I26,FIND(":",I26)-1)+RIGHT(I26,LEN(I26)-FIND(":",I26))/60) -> 146 | U26: =ASIN(N26/J26)*180/PI() -> 0 | W26: =J26*COS(U26*PI()/180) -> 30.4 | X26: =J26*SIN(U26*PI()/180) -> 0 | Y26: =IF(R26="-",IF(S26>180,S26-180,S26+180),R26) -> 146 | Z26: =IF('Raw Data'!O26="","",O25+N25)
A27: =IF('Raw Data'!A27="","",'Raw Data'!A27) -> B1 | B27: =IF('Raw Data'!B27="","",'Raw Data'!B27) -> C1 | C27: =IF('Raw Data'!C27="","",'Raw Data'!C27) -> 4 | D27: =IF('Raw Data'!D27="","",'Raw Data'!D27) -> 1 | E27: =IF('Raw Data'!E27="","",'Raw Data'!E27) -> 10 | F27: =IF('Raw Data'!F27="","",'Raw Data'!F27) -> 2 | G27: =IF('Raw Data'!G27="/","-",IF('Raw Data'!G27="","-",SUBSTITUTE('Raw Data'!G27," ",":",1))) -> 248 | H27: =IF('Raw Data'!H27="/","-",IF('Raw Data'!H27="","-",SUBSTITUTE('Raw Data'!H27," ",":",1))) -> - | I27: =IF('Raw Data'!I27="/","-",IF('Raw Data'!I27="","-",SUBSTITUTE('Raw Data'!I27," ",":",1))) -> 248 | J27: =IF('Raw Data'!J27="",IF(LEN(K27)>6,SQRT('Raw Data'!M27^2+N27^2),""),'Raw Data'!J27) -> 37.5 | K27: =IF('Raw Data'!K27="","",IF(LEN('Raw Data'!K27)<7,SUBSTITUTE('Raw Data'!K27," ",":",1),'Raw Data'!K27)) -> -6:00 | L27: =IF('Raw Data'!L27="","",'Raw Data'!L27) | M27: =IF('Raw Data'!M27="","",'Raw Data'!M27) -> 37.3 | N27: =IF('Raw Data'!N27="","",IF('Raw Data'!N27="-",0,'Raw Data'!N27)) -> -3.9 | O27: =IF('Raw Data'!O27="",IF('Raw Data'!N27="","",0),'Raw Data'!O27) -> 11 | P27: =IF('Raw Data'!P27="","",'Raw Data'!P27) -> B1 is ent to P.G. pass, above stalagmite keloid (sp.?) | Q27: =" " | R27: =IF(ISERROR(FIND(":",G27)),IF(G27<>"-",1*G27,G27),1*LEFT(G27,FIND(":",G27)-1)+RIGHT(G27,LEN(G27)-FIND(":",G27))/60) -> 248 | S27: =IF(ISERROR(FIND(":",H27)),IF(H27<>"-",1*H27,H27),1*LEFT(H27,FIND(":",H27)-1)+RIGHT(H27,LEN(H27)-FIND(":",H27))/60) -> - | T27: =IF(ISERROR(FIND(":",I27)),IF(I27<>"-",1*I27,I27),1*LEFT(I27,FIND(":",I27)-1)+RIGHT(I27,LEN(I27)-FIND(":",I27))/60) -> 248 | U27: =IF(ISERROR(FIND(":",K27)),IF(K27="zero",0,1*K27),1*CONCATENATE(LEFT(K27,FIND(":",K27)-1),".",MID(RIGHT(K27,LEN(K27)-FIND(":",K27))/60,3,8))) -> -6 | W27: =J27*COS(U27*PI()/180) -> 37.294571 | X27: =J27*SIN(U27*PI()/180) -> -3.9198174 | Y27: =IF(R27="-",IF(S27>180,S27-180,S27+180),R27) -> 248 | Z27: =IF('Raw Data'!O27="","",O26-N31-N30-N27) -> 11
A28: =IF('Raw Data'!A28="","",'Raw Data'!A28) -> p. 47-50 | B28: =IF('Raw Data'!B28="","",'Raw Data'!B28) -> (=PDF p.51-54) | C28: =IF('Raw Data'!C28="","",'Raw Data'!C28) | D28: =IF('Raw Data'!D28="","",'Raw Data'!D28) | E28: =IF('Raw Data'!E28="","",'Raw Data'!E28) | F28: =IF('Raw Data'!F28="","",'Raw Data'!F28) | G28: =IF('Raw Data'!G28="/","-",IF('Raw Data'!G28="","-",SUBSTITUTE('Raw Data'!G28," ",":",1))) -> - | H28: =IF('Raw Data'!H28="/","-",IF('Raw Data'!H28="","-",SUBSTITUTE('Raw Data'!H28," ",":",1))) -> - | I28: =IF('Raw Data'!I28="/","-",IF('Raw Data'!I28="","-",SUBSTITUTE('Raw Data'!I28," ",":",1))) -> - | J28: =IF('Raw Data'!J28="",IF(LEN(K28)>6,SQRT('Raw Data'!M28^2+N28^2),""),'Raw Data'!J28) | K28: =IF('Raw Data'!K28="","",IF(LEN('Raw Data'!K28)<7,SUBSTITUTE('Raw Data'!K28," ",":",1),'Raw Data'!K28)) | L28: =IF('Raw Data'!L28="","",'Raw Data'!L28) | M28: =IF('Raw Data'!M28="","",'Raw Data'!M28) | N28: =IF('Raw Data'!N28="","",IF('Raw Data'!N28="-",0,'Raw Data'!N28)) | O28: =IF('Raw Data'!O28="",IF('Raw Data'!N28="","",0),'Raw Data'!O28) | P28: =IF('Raw Data'!P28="","",'Raw Data'!P28) | Q28: =" " | Z28: =IF('Raw Data'!O28="","",O27+N27)
A29: =IF('Raw Data'!A29="","",'Raw Data'!A29) -> 5th August 1951 | B29: =IF('Raw Data'!B29="","",'Raw Data'!B29) -> SWILDONS HOLE SURVEY | C29: =IF('Raw Data'!C29="","",'Raw Data'!C29) | D29: =IF('Raw Data'!D29="","",'Raw Data'!D29) | E29: =IF('Raw Data'!E29="","",'Raw Data'!E29) | F29: =IF('Raw Data'!F29="","",'Raw Data'!F29) | G29: =IF('Raw Data'!G29="/","-",IF('Raw Data'!G29="","-",SUBSTITUTE('Raw Data'!G29," ",":",1))) -> - | H29: =IF('Raw Data'!H29="/","-",IF('Raw Data'!H29="","-",SUBSTITUTE('Raw Data'!H29," ",":",1))) -> - | I29: =IF('Raw Data'!I29="/","-",IF('Raw Data'!I29="","-",SUBSTITUTE('Raw Data'!I29," ",":",1))) -> - | J29: =IF('Raw Data'!J29="",IF(LEN(K29)>6,SQRT('Raw Data'!M29^2+N29^2),""),'Raw Data'!J29) | K29: =IF('Raw Data'!K29="","",IF(LEN('Raw Data'!K29)<7,SUBSTITUTE('Raw Data'!K29," ",":",1),'Raw Data'!K29)) | L29: =IF('Raw Data'!L29="","",'Raw Data'!L29) | M29: =IF('Raw Data'!M29="","",'Raw Data'!M29) -> CONTINUED | N29: =IF('Raw Data'!N29="","",IF('Raw Data'!N29="-",0,'Raw Data'!N29)) | O29: =IF('Raw Data'!O29="",IF('Raw Data'!N29="","",0),'Raw Data'!O29) -> Compass bearings magnetic 11(deg)30' W | P29: =IF('Raw Data'!P29="","",'Raw Data'!P29) | Q29: =" "
A30: =IF('Raw Data'!A30="","",'Raw Data'!A30) -> C1 | B30: =IF('Raw Data'!B30="","",'Raw Data'!B30) -> D1 | C30: =IF('Raw Data'!C30="","",'Raw Data'!C30) -> 5 | D30: =IF('Raw Data'!D30="","",'Raw Data'!D30) -> 6 | E30: =IF('Raw Data'!E30="","",'Raw Data'!E30) -> 15 | F30: =IF('Raw Data'!F30="","",'Raw Data'!F30) -> 4 | G30: =IF('Raw Data'!G30="/","-",IF('Raw Data'!G30="","-",SUBSTITUTE('Raw Data'!G30," ",":",1))) -> - | H30: =IF('Raw Data'!H30="/","-",IF('Raw Data'!H30="","-",SUBSTITUTE('Raw Data'!H30," ",":",1))) -> 85 | I30: =IF('Raw Data'!I30="/","-",IF('Raw Data'!I30="","-",SUBSTITUTE('Raw Data'!I30," ",":",1))) -> 265 | J30: =IF('Raw Data'!J30="",IF(LEN(K30)>6,SQRT('Raw Data'!M30^2+N30^2),""),'Raw Data'!J30) -> 11.8 | K30: =IF('Raw Data'!K30="","",IF(LEN('Raw Data'!K30)<7,SUBSTITUTE('Raw Data'!K30," ",":",1),'Raw Data'!K30)) -> -24 | L30: =IF('Raw Data'!L30="","",'Raw Data'!L30) | M30: =IF('Raw Data'!M30="","",'Raw Data'!M30) -> 10.8 | N30: =IF('Raw Data'!N30="","",IF('Raw Data'!N30="-",0,'Raw Data'!N30)) -> -4.8 | O30: =IF('Raw Data'!O30="",IF('Raw Data'!N30="","",0),'Raw Data'!O30) -> 7.1 | P30: =IF('Raw Data'!P30="","",'Raw Data'!P30) -> On rocky bank. | Q30: =" " | R30: =IF(ISERROR(FIND(":",G30)),IF(G30<>"-",1*G30,G30),1*LEFT(G30,FIND(":",G30)-1)+RIGHT(G30,LEN(G30)-FIND(":",G30))/60) -> - | S30: =IF(ISERROR(FIND(":",H30)),IF(H30<>"-",1*H30,H30),1*LEFT(H30,FIND(":",H30)-1)+RIGHT(H30,LEN(H30)-FIND(":",H30))/60) -> 85 | T30: =IF(ISERROR(FIND(":",I30)),IF(I30<>"-",1*I30,I30),1*LEFT(I30,FIND(":",I30)-1)+RIGHT(I30,LEN(I30)-FIND(":",I30))/60) -> 265 | U30: =IF(ISERROR(FIND(":",K30)),IF(K30="zero",0,1*K30),1*CONCATENATE(LEFT(K30,FIND(":",K30)-1),".",MID(RIGHT(K30,LEN(K30)-FIND(":",K30))/60,3,8))) -> -24 | W30: =J30*COS(U30*PI()/180) -> 10.779836 | X30: =J30*SIN(U30*PI()/180) -> -4.7994924 | Y30: =IF(R30="-",IF(S30>180,S30-180,S30+180),R30) -> 265 | Z30: =IF('Raw Data'!O30="","",O27+N27) -> 7.1
